Workbook

Sheet поверки
B3: Реестр сведений о результатах поверки СИ
B4: Выборка по: Дата поверки: "2025-04-01" - "2025-04-30" | W4: Копировать для выгрзуки в журнал на сайт
A5: Номер | B5: Дата изменения | C5: Автор записи | D5: Владелец СИ | E5: Тип СИ | F5: Рег. номер типа СИ | G5: Дата поверки | H5: Заводской №/ Буквенно-цифровое обозначение | I5: Разряд эталона | J5: Статус | K5: Пригодность | L5: Документ | M5: Дубль | N5: Дубль № документа | O5: ном_по_порядку_с_начала_месяца | P5: номер_протокола | Q5: Наименование СИ | R5: Поверитель | S5: ТипСИ | T5: № акта | U5: Дата приемки | V5: Дата выдачи | W5: Столбец7 | X5: Столбец8 | Y5: Столбец9 | Z5: ДляАкта
B6: 29.04.2025 08:48 | C6: Проскурякова Елена Львовна | D6: ООО "РИ-ИНВЕСТ" | F6: 15771-10 | G6: 45748 | H6: 205/M/S7-200 | J6: Опубликован | K6: Да | L6: С-ЕЖБ/01-04-2025/429338896 | N6: =IF(COUNTIF(поверки!$L$6:$L$3175,поверки!$L6)>1,"Дубликат","") | O6: 1 | P6: =CONCATENATE(TEXT(MONTH(поверки!$G6),"00"),"/",TEXT(поверки!$O6,"000"), "/",TEXT(YEAR(поверки!$G6)-2000,"00")) -> 04/001/25 | Q6: =VLOOKUP(поверки!$F6,'соответстиви ОТ типу'!$K$4:$M$344,2,FALSE()) -> Контроллер | R6: Кадыков П.Ю. | S6: Simatic S7-200 | T6: 1 | U6: =VLOOKUP(поверки!$T6,'Акты п-п'!$C$5:$I$57,2,FALSE()) -> 45748 | V6: =VLOOKUP(поверки!$T6,'Акты п-п'!$C$5:$I$57,3,FALSE()) -> 45751 | W6: =VLOOKUP(поверки!$T6,'Акты п-п'!$C$5:$I$57,5,FALSE()) -> Чупин А.А. | X6: =поверки!$G6-поверки!$U6 -> 0 | Y6: =поверки!$V6-поверки!$G6 -> 3 | Z6: =CONCATENATE(поверки!$Q6," ",поверки!$S6," номер ",поверки!$H6) -> Контроллер Simatic S7-200 номер 205/M/S7-200
B7: 29.04.2025 08:48 | C7: Проскурякова Елена Львовна | D7: ООО "РИ-ИНВЕСТ" | F7: 15772-11 | G7: 45748 | H7: 205/BMS01/S7-300 | J7: Опубликован | K7: Да | L7: С-ЕЖБ/01-04-2025/429338895 | N7: =IF(COUNTIF(поверки!$L$6:$L$3175,поверки!$L7)>1,"Дубликат","") | O7: 2 | P7: =CONCATENATE(TEXT(MONTH(поверки!$G7),"00"),"/",TEXT(поверки!$O7,"000"), "/",TEXT(YEAR(поверки!$G7)-2000,"00")) -> 04/002/25 | Q7: =VLOOKUP(поверки!$F7,'соответстиви ОТ типу'!$K$4:$M$344,2,FALSE()) -> Контроллер | R7: Чупин А.А. | S7: Simatic S7-300 | T7: 1 | U7: =VLOOKUP(поверки!$T7,'Акты п-п'!$C$5:$I$57,2,FALSE()) -> 45748 | V7: =VLOOKUP(поверки!$T7,'Акты п-п'!$C$5:$I$57,3,FALSE()) -> 45751 | W7: =VLOOKUP(поверки!$T7,'Акты п-п'!$C$5:$I$57,5,FALSE()) -> Чупин А.А. | X7: =поверки!$G7-поверки!$U7 -> 0 | Y7: =поверки!$V7-поверки!$G7 -> 3 | Z7: =CONCATENATE(поверки!$Q7," ",поверки!$S7," номер ",поверки!$H7) -> Контроллер Simatic S7-300 номер 205/BMS01/S7-300
B8: 29.04.2025 08:48 | C8: Проскурякова Елена Львовна | D8: ООО "РИ-ИНВЕСТ" | F8: 15772-11 | G8: 45748 | H8: 205/BMS02/S7-300 | J8: Опубликован | K8: Да | L8: С-ЕЖБ/01-04-2025/429338894 | N8: =IF(COUNTIF(поверки!$L$6:$L$3175,поверки!$L8)>1,"Дубликат","") | O8: 3 | P8: =CONCATENATE(TEXT(MONTH(поверки!$G8),"00"),"/",TEXT(поверки!$O8,"000"), "/",TEXT(YEAR(поверки!$G8)-2000,"00")) -> 04/003/25 | Q8: =VLOOKUP(поверки!$F8,'соответстиви ОТ типу'!$K$4:$M$344,2,FALSE()) -> Контроллер | R8: Большаков С.Н. | S8: Simatic S7-300 | T8: 1 | U8: =VLOOKUP(поверки!$T8,'Акты п-п'!$C$5:$I$57,2,FALSE()) -> 45748 | V8: =VLOOKUP(поверки!$T8,'Акты п-п'!$C$5:$I$57,3,FALSE()) -> 45751 | W8: =VLOOKUP(поверки!$T8,'Акты п-п'!$C$5:$I$57,5,FALSE()) -> Чупин А.А. | X8: =поверки!$G8-поверки!$U8 -> 0 | Y8: =поверки!$V8-поверки!$G8 -> 3 | Z8: =CONCATENATE(поверки!$Q8," ",поверки!$S8," номер ",поверки!$H8) -> Контроллер Simatic S7-300 номер 205/BMS02/S7-300
B9: 17.04.2025 14:03 | C9: Проскурякова Елена Львовна | D9: ООО "ГАЗПРОМНЕФТЬ-ЯМАЛ" | F9: 54782-13 | G9: 45748 | H9: ER150099 | J9: Опубликован | K9: Да | L9: С-ЕЖБ/01-04-2025/426244275 | M9: =IF(COUNTIF(поверки!$H$6:$H$3175,поверки!$H9)>1,"Дубликат","") | N9: =IF(COUNTIF(поверки!$L$6:$L$3175,поверки!$L9)>1,"Дубликат","") | O9: 4 | P9: =CONCATENATE(TEXT(MONTH(поверки!$G9),"00"),"/",TEXT(поверки!$O9,"000"), "/",TEXT(YEAR(поверки!$G9)-2000,"00")) -> 04/004/25 | Q9: =VLOOKUP(поверки!$F9,'соответстиви ОТ типу'!$K$4:$M$344,2,FALSE()) -> Газоанализатор ЭРИС-ОПТИМА ПЛЮС | R9: Манджеев А.А. | S9: ЭРИС-ОПТИМА ПЛЮС М | T9: 2 | U9: =VLOOKUP(поверки!$T9,'Акты п-п'!$C$5:$I$57,2,FALSE()) -> 45748 | V9: =VLOOKUP(поверки!$T9,'Акты п-п'!$C$5:$I$57,3,FALSE()) -> 45754 | W9: =VLOOKUP(поверки!$T9,'Акты п-п'!$C$5:$I$57,5,FALSE()) -> Манджеев А.А. | X9: =поверки!$G9-поверки!$U9 -> 0 | Y9: =поверки!$V9-поверки!$G9 -> 6 | Z9: =CONCATENATE(поверки!$Q9," ",поверки!$S9," номер ",поверки!$H9) -> Газоанализатор ЭРИС-ОПТИМА ПЛЮС ЭРИС-ОПТИМА ПЛЮС М номер ER150099
B10: 17.04.2025 14:03 | C10: Проскурякова Елена Львовна | D10: ООО "ГАЗПРОМНЕФТЬ-ЯМАЛ" | F10: 61878-15 | G10: 45748 | H10: Z0182517390061 | J10: Опубликован | K10: Да | L10: С-ЕЖБ/01-04-2025/426244274 | M10: =IF(COUNTIF(поверки!$H$6:$H$3175,поверки!$H10)>1,"Дубликат","") | N10: =IF(COUNTIF(поверки!$L$6:$L$3175,поверки!$L10)>1,"Дубликат","") | O10: 5 | P10: =CONCATENATE(TEXT(MONTH(поверки!$G10),"00"),"/",TEXT(поверки!$O10,"000"), "/",TEXT(YEAR(поверки!$G10)-2000,"00")) -> 04/005/25 | Q10: =VLOOKUP(поверки!$F10,'соответстиви ОТ типу'!$K$4:$M$344,2,FALSE()) -> Датчик горючих газов | R10: Манджеев А.А. | S10: Searchpoint Optima Plus XTC | T10: 2 | U10: =VLOOKUP(поверки!$T10,'Акты п-п'!$C$5:$I$57,2,FALSE()) -> 45748 | V10: =VLOOKUP(поверки!$T10,'Акты п-п'!$C$5:$I$57,3,FALSE()) -> 45754 | W10: =VLOOKUP(поверки!$T10,'Акты п-п'!$C$5:$I$57,5,FALSE()) -> Манджеев А.А. | X10: =поверки!$G10-поверки!$U10 -> 0 | Y10: =поверки!$V10-поверки!$G10 -> 6 | Z10: =CONCATENATE(поверки!$Q10," ",поверки!$S10," номер ",поверки!$H10) -> Датчик горючих газов Searchpoint Optima Plus XTC номер Z0182517390061
B11: 17.04.2025 14:03 | C11: Проскурякова Елена Львовна | D11: ООО "ГАЗПРОМНЕФТЬ-ЯМАЛ" | F11: 61878-15 | G11: 45748 | H11: Z0182517390036 | J11: Опубликован | K11: Да | L11: С-ЕЖБ/01-04-2025/426244273 | M11: =IF(COUNTIF(поверки!$H$6:$H$3175,поверки!$H11)>1,"Дубликат","") | N11: =IF(COUNTIF(поверки!$L$6:$L$3175,поверки!$L11)>1,"Дубликат","") | O11: 6 | P11: =CONCATENATE(TEXT(MONTH(поверки!$G11),"00"),"/",TEXT(поверки!$O11,"000"), "/",TEXT(YEAR(поверки!$G11)-2000,"00")) -> 04/006/25 | Q11: =VLOOKUP(поверки!$F11,'соответстиви ОТ типу'!$K$4:$M$344,2,FALSE()) -> Датчик горючих газов | R11: Манджеев А.А. | S11: Searchpoint Optima Plus XTC | T11: 2 | U11: =VLOOKUP(поверки!$T11,'Акты п-п'!$C$5:$I$57,2,FALSE()) -> 45748 | V11: =VLOOKUP(поверки!$T11,'Акты п-п'!$C$5:$I$57,3,FALSE()) -> 45754 | W11: =VLOOKUP(поверки!$T11,'Акты п-п'!$C$5:$I$57,5,FALSE()) -> Манджеев А.А. | X11: =поверки!$G11-поверки!$U11 -> 0 | Y11: =поверки!$V11-поверки!$G11 -> 6 | Z11: =CONCATENATE(поверки!$Q11," ",поверки!$S11," номер ",поверки!$H11) -> Датчик горючих газов Searchpoint Optima Plus XTC номер Z0182517390036
B12: 26.05.2025 09:29 | C12: Проскурякова Елена Львовна | D12: ООО "РИ-ИНВЕСТ" | E12: Преобразователи (датчики) давления измерительные | F12: 59868-15 | G12: 45749 | H12: 91R808434 | J12: Опубликован | K12: Да | L12: С-ЕЖБ/02-04-2025/429337800 | M12: =IF(COUNTIF(поверки!$H$6:$H$3175,поверки!$H12)>1,"Дубликат","") | N12: =IF(COUNTIF(поверки!$L$6:$L$3175,поверки!$L12)>1,"Дубликат","") | O12: 7 | P12: =CONCATENATE(TEXT(MONTH(поверки!$G12),"00"),"/",TEXT(поверки!$O12,"000"), "/",TEXT(YEAR(поверки!$G12)-2000,"00")) -> 04/007/25 | Q12: =VLOOKUP(поверки!$F12,'соответстиви ОТ типу'!$K$4:$M$344,2,FALSE()) -> Преобразователь давления | R12: Кадыков П.Ю. | S12: EJX 530A | T12: 1 | U12: =VLOOKUP(поверки!$T12,'Акты п-п'!$C$5:$I$57,2,FALSE()) -> 45748 | V12: =VLOOKUP(поверки!$T12,'Акты п-п'!$C$5:$I$57,3,FALSE()) -> 45751 | W12: =VLOOKUP(поверки!$T12,'Акты п-п'!$C$5:$I$57,5,FALSE()) -> Чупин А.А. | X12: =поверки!$G12-поверки!$U12 -> 1 | Y12: =поверки!$V12-поверки!$G12 -> 2 | Z12: =CONCATENATE(поверки!$Q12," ",поверки!$S12," номер ",поверки!$H12) -> Преобразователь давления EJX 530A номер 91R808434
B13: 29.04.2025 12:17 | C13: Проскурякова Елена Львовна | D13: ООО "РИ-ИНВЕСТ" | F13: 23410-08 | G13: 45749 | H13: 2080951 | J13: Опубликован | K13: Да | L13: С-ЕЖБ/02-04-2025/429422996 | M13: =IF(COUNTIF(поверки!$H$6:$H$3175,поверки!$H13)>1,"Дубликат","") | N13: =IF(COUNTIF(поверки!$L$6:$L$3175,поверки!$L13)>1,"Дубликат","") | O13: 8 | P13: =CONCATENATE(TEXT(MONTH(поверки!$G13),"00"),"/",TEXT(поверки!$O13,"000"), "/",TEXT(YEAR(поверки!$G13)-2000,"00")) -> 04/008/25 | Q13: =VLOOKUP(поверки!$F13,'соответстиви ОТ типу'!$K$4:$M$344,2,FALSE()) -> Датчик температуры | R13: Кадыков П.Ю. | S13: Метран-286-02 | T13: 1 | U13: =VLOOKUP(поверки!$T13,'Акты п-п'!$C$5:$I$57,2,FALSE()) -> 45748 | V13: =VLOOKUP(поверки!$T13,'Акты п-п'!$C$5:$I$57,3,FALSE()) -> 45751 | W13: =VLOOKUP(поверки!$T13,'Акты п-п'!$C$5:$I$57,5,FALSE()) -> Чупин А.А. | X13: =поверки!$G13-поверки!$U13 -> 1 | Y13: =поверки!$V13-поверки!$G13 -> 2 | Z13: =CONCATENATE(поверки!$Q13," ",поверки!$S13," номер ",поверки!$H13) -> Датчик температуры Метран-286-02 номер 2080951
B14: 29.04.2025 12:17 | C14: Проскурякова Елена Львовна | D14: ООО "РИ-ИНВЕСТ" | F14: 50519-12 | G14: 45749 | H14: 12-9083 | J14: Опубликован | K14: Да | L14: С-ЕЖБ/02-04-2025/429422995 | M14: =IF(COUNTIF(поверки!$H$6:$H$3175,поверки!$H14)>1,"Дубликат","") | N14: =IF(COUNTIF(поверки!$L$6:$L$3175,поверки!$L14)>1,"Дубликат","") | O14: 9 | P14: =CONCATENATE(TEXT(MONTH(поверки!$G14),"00"),"/",TEXT(поверки!$O14,"000"), "/",TEXT(YEAR(поверки!$G14)-2000,"00")) -> 04/009/25 | Q14: =VLOOKUP(поверки!$F14,'соответстиви ОТ типу'!$K$4:$M$344,2,FALSE()) -> Датчик температуры | R14: Кадыков П.Ю. | S14: ТПУ 0304Ех | T14: 1 | U14: =VLOOKUP(поверки!$T14,'Акты п-п'!$C$5:$I$57,2,FALSE()) -> 45748 | V14: =VLOOKUP(поверки!$T14,'Акты п-п'!$C$5:$I$57,3,FALSE()) -> 45751 | W14: =VLOOKUP(поверки!$T14,'Акты п-п'!$C$5:$I$57,5,FALSE()) -> Чупин А.А. | X14: =поверки!$G14-поверки!$U14 -> 1 | Y14: =поверки!$V14-поверки!$G14 -> 2 | Z14: =CONCATENATE(поверки!$Q14," ",поверки!$S14," номер ",поверки!$H14) -> Датчик температуры ТПУ 0304Ех номер 12-9083
B15: 29.04.2025 12:17 | C15: Проскурякова Елена Львовна | D15: ООО "РИ-ИНВЕСТ" | F15: 50519-12 | G15: 45749 | H15: 12-9082 | J15: Опубликован | K15: Да | L15: С-ЕЖБ/02-04-2025/429422993 | N15: =IF(COUNTIF(поверки!$L$6:$L$3175,поверки!$L15)>1,"Дубликат","") | O15: 10 | P15: =CONCATENATE(TEXT(MONTH(поверки!$G15),"00"),"/",TEXT(поверки!$O15,"000"), "/",TEXT(YEAR(поверки!$G15)-2000,"00")) -> 04/010/25 | Q15: =VLOOKUP(поверки!$F15,'соответстиви ОТ типу'!$K$4:$M$344,2,FALSE()) -> Датчик температуры | R15: Кадыков П.Ю. | S15: ТПУ 0304Ех | T15: 1 | U15: =VLOOKUP(поверки!$T15,'Акты п-п'!$C$5:$I$57,2,FALSE()) -> 45748 | V15: =VLOOKUP(поверки!$T15,'Акты п-п'!$C$5:$I$57,3,FALSE()) -> 45751 | W15: =VLOOKUP(поверки!$T15,'Акты п-п'!$C$5:$I$57,5,FALSE()) -> Чупин А.А. | X15: =поверки!$G15-поверки!$U15 -> 1 | Y15: =поверки!$V15-поверки!$G15 -> 2 | Z15: =CONCATENATE(поверки!$Q15," ",поверки!$S15," номер ",поверки!$H15) -> Датчик температуры ТПУ 0304Ех номер 12-9082
B16: 29.04.2025 12:17 | C16: Проскурякова Елена Львовна | D16: ООО "РИ-ИНВЕСТ" | F16: 50519-12 | G16: 45749 | H16: 12-9078 | J16: Опубликован | K16: Да | L16: С-ЕЖБ/02-04-2025/429422991 | N16: =IF(COUNTIF(поверки!$L$6:$L$3175,поверки!$L16)>1,"Дубликат","") | O16: 11 | P16: =CONCATENATE(TEXT(MONTH(поверки!$G16),"00"),"/",TEXT(поверки!$O16,"000"), "/",TEXT(YEAR(поверки!$G16)-2000,"00")) -> 04/011/25 | Q16: =VLOOKUP(поверки!$F16,'соответстиви ОТ типу'!$K$4:$M$344,2,FALSE()) -> Датчик температуры | R16: Кадыков П.Ю. | S16: ТПУ 0304Ех | T16: 1 | U16: =VLOOKUP(поверки!$T16,'Акты п-п'!$C$5:$I$57,2,FALSE()) -> 45748 | V16: =VLOOKUP(поверки!$T16,'Акты п-п'!$C$5:$I$57,3,FALSE()) -> 45751 | W16: =VLOOKUP(поверки!$T16,'Акты п-п'!$C$5:$I$57,5,FALSE()) -> Чупин А.А. | X16: =поверки!$G16-поверки!$U16 -> 1 | Y16: =поверки!$V16-поверки!$G16 -> 2 | Z16: =CONCATENATE(поверки!$Q16," ",поверки!$S16," номер ",поверки!$H16) -> Датчик температуры ТПУ 0304Ех номер 12-9078
B17: 29.04.2025 12:17 | C17: Проскурякова Елена Львовна | D17: ООО "РИ-ИНВЕСТ" | F17: 50519-12 | G17: 45749 | H17: 12-9086 | J17: Опубликован | K17: Да | L17: С-ЕЖБ/02-04-2025/429422990 | N17: =IF(COUNTIF(поверки!$L$6:$L$3175,поверки!$L17)>1,"Дубликат","") | O17: 12 | P17: =CONCATENATE(TEXT(MONTH(поверки!$G17),"00"),"/",TEXT(поверки!$O17,"000"), "/",TEXT(YEAR(поверки!$G17)-2000,"00")) -> 04/012/25 | Q17: =VLOOKUP(поверки!$F17,'соответстиви ОТ типу'!$K$4:$M$344,2,FALSE()) -> Датчик температуры | R17: Кадыков П.Ю. | S17: ТПУ 0304Ех | T17: 1 | U17: =VLOOKUP(поверки!$T17,'Акты п-п'!$C$5:$I$57,2,FALSE()) -> 45748 | V17: =VLOOKUP(поверки!$T17,'Акты п-п'!$C$5:$I$57,3,FALSE()) -> 45751 | W17: =VLOOKUP(поверки!$T17,'Акты п-п'!$C$5:$I$57,5,FALSE()) -> Чупин А.А. | X17: =поверки!$G17-поверки!$U17 -> 1 | Y17: =поверки!$V17-поверки!$G17 -> 2 | Z17: =CONCATENATE(поверки!$Q17," ",поверки!$S17," номер ",поверки!$H17) -> Датчик температуры ТПУ 0304Ех номер 12-9086
B18: 29.04.2025 12:17 | C18: Проскурякова Елена Львовна | D18: ООО "РИ-ИНВЕСТ" | F18: 50519-12 | G18: 45749 | H18: 12-9089 | J18: Опубликован | K18: Да | L18: С-ЕЖБ/02-04-2025/429422986 | N18: =IF(COUNTIF(поверки!$L$6:$L$3175,поверки!$L18)>1,"Дубликат","") | O18: 13 | P18: =CONCATENATE(TEXT(MONTH(поверки!$G18),"00"),"/",TEXT(поверки!$O18,"000"), "/",TEXT(YEAR(поверки!$G18)-2000,"00")) -> 04/013/25 | Q18: =VLOOKUP(поверки!$F18,'соответстиви ОТ типу'!$K$4:$M$344,2,FALSE()) -> Датчик температуры | R18: Кадыков П.Ю. | S18: ТПУ 0304Ех | T18: 1 | U18: =VLOOKUP(поверки!$T18,'Акты п-п'!$C$5:$I$57,2,FALSE()) -> 45748 | V18: =VLOOKUP(поверки!$T18,'Акты п-п'!$C$5:$I$57,3,FALSE()) -> 45751 | W18: =VLOOKUP(поверки!$T18,'Акты п-п'!$C$5:$I$57,5,FALSE()) -> Чупин А.А. | X18: =поверки!$G18-поверки!$U18 -> 1 | Y18: =поверки!$V18-поверки!$G18 -> 2 | Z18: =CONCATENATE(поверки!$Q18," ",поверки!$S18," номер ",поверки!$H18) -> Датчик температуры ТПУ 0304Ех номер 12-9089
B19: 29.04.2025 12:17 | C19: Проскурякова Елена Львовна | D19: ООО "РИ-ИНВЕСТ" | F19: 50519-12 | G19: 45749 | H19: 12-9079 | J19: Опубликован | K19: Да | L19: С-ЕЖБ/02-04-2025/429422977 | N19: =IF(COUNTIF(поверки!$L$6:$L$3175,поверки!$L19)>1,"Дубликат","") | O19: 14 | P19: =CONCATENATE(TEXT(MONTH(поверки!$G19),"00"),"/",TEXT(поверки!$O19,"000"), "/",TEXT(YEAR(поверки!$G19)-2000,"00")) -> 04/014/25 | Q19: =VLOOKUP(поверки!$F19,'соответстиви ОТ типу'!$K$4:$M$344,2,FALSE()) -> Датчик температуры | R19: Кадыков П.Ю. | S19: ТПУ 0304Ех | T19: 1 | U19: =VLOOKUP(поверки!$T19,'Акты п-п'!$C$5:$I$57,2,FALSE()) -> 45748 | V19: =VLOOKUP(поверки!$T19,'Акты п-п'!$C$5:$I$57,3,FALSE()) -> 45751 | W19: =VLOOKUP(поверки!$T19,'Акты п-п'!$C$5:$I$57,5,FALSE()) -> Чупин А.А. | X19: =поверки!$G19-поверки!$U19 -> 1 | Y19: =поверки!$V19-поверки!$G19 -> 2 | Z19: =CONCATENATE(поверки!$Q19," ",поверки!$S19," номер ",поверки!$H19) -> Датчик температуры ТПУ 0304Ех номер 12-9079
B20: 29.04.2025 12:17 | C20: Проскурякова Елена Львовна | D20: ООО "РИ-ИНВЕСТ" | F20: 28033-05 | G20: 45749 | H20: 02244553/03221492 | J20: Опубликован | K20: Да | L20: С-ЕЖБ/02-04-2025/429422975 | N20: =IF(COUNTIF(поверки!$L$6:$L$3175,поверки!$L20)>1,"Дубликат","") | O20: 15 | P20: =CONCATENATE(TEXT(MONTH(поверки!$G20),"00"),"/",TEXT(поверки!$O20,"000"), "/",TEXT(YEAR(поверки!$G20)-2000,"00")) -> 04/015/25 | Q20: =VLOOKUP(поверки!$F20,'соответстиви ОТ типу'!$K$4:$M$344,2,FALSE()) -> Датчик температуры | R20: Кадыков П.Ю. | S20: 248 | T20: 1 | U20: =VLOOKUP(поверки!$T20,'Акты п-п'!$C$5:$I$57,2,FALSE()) -> 45748 | V20: =VLOOKUP(поверки!$T20,'Акты п-п'!$C$5:$I$57,3,FALSE()) -> 45751 | W20: =VLOOKUP(поверки!$T20,'Акты п-п'!$C$5:$I$57,5,FALSE()) -> Чупин А.А. | X20: =поверки!$G20-поверки!$U20 -> 1 | Y20: =поверки!$V20-поверки!$G20 -> 2 | Z20: =CONCATENATE(поверки!$Q20," ",поверки!$S20," номер ",поверки!$H20) -> Датчик температуры 248 номер 02244553/03221492
B21: 29.04.2025 12:17 | C21: Проскурякова Елена Львовна | D21: ООО "РИ-ИНВЕСТ" | F21: 28033-05 | G21: 45749 | H21: 02244527/03221466 | J21: Опубликован | K21: Да | L21: С-ЕЖБ/02-04-2025/429422974 | N21: =IF(COUNTIF(поверки!$L$6:$L$3175,поверки!$L21)>1,"Дубликат","") | O21: 16 | P21: =CONCATENATE(TEXT(MONTH(поверки!$G21),"00"),"/",TEXT(поверки!$O21,"000"), "/",TEXT(YEAR(поверки!$G21)-2000,"00")) -> 04/016/25 | Q21: =VLOOKUP(поверки!$F21,'соответстиви ОТ типу'!$K$4:$M$344,2,FALSE()) -> Датчик температуры | R21: Кадыков П.Ю. | S21: 248 | T21: 1 | U21: =VLOOKUP(поверки!$T21,'Акты п-п'!$C$5:$I$57,2,FALSE()) -> 45748 | V21: =VLOOKUP(поверки!$T21,'Акты п-п'!$C$5:$I$57,3,FALSE()) -> 45751 | W21: =VLOOKUP(поверки!$T21,'Акты п-п'!$C$5:$I$57,5,FALSE()) -> Чупин А.А. | X21: =поверки!$G21-поверки!$U21 -> 1 | Y21: =поверки!$V21-поверки!$G21 -> 2 | Z21: =CONCATENATE(поверки!$Q21," ",поверки!$S21," номер ",поверки!$H21) -> Датчик температуры 248 номер 02244527/03221466
B22: 29.04.2025 12:17 | C22: Проскурякова Елена Львовна | D22: ООО "РИ-ИНВЕСТ" | F22: 28033-05 | G22: 45749 | H22: 02244851/03221643 | J22: Опубликован | K22: Да | L22: С-ЕЖБ/02-04-2025/429422972 | N22: =IF(COUNTIF(поверки!$L$6:$L$3175,поверки!$L22)>1,"Дубликат","") | O22: 17 | P22: =CONCATENATE(TEXT(MONTH(поверки!$G22),"00"),"/",TEXT(поверки!$O22,"000"), "/",TEXT(YEAR(поверки!$G22)-2000,"00")) -> 04/017/25 | Q22: =VLOOKUP(поверки!$F22,'соответстиви ОТ типу'!$K$4:$M$344,2,FALSE()) -> Датчик температуры | R22: Кадыков П.Ю. | S22: 248 | T22: 1 | U22: =VLOOKUP(поверки!$T22,'Акты п-п'!$C$5:$I$57,2,FALSE()) -> 45748 | V22: =VLOOKUP(поверки!$T22,'Акты п-п'!$C$5:$I$57,3,FALSE()) -> 45751 | W22: =VLOOKUP(поверки!$T22,'Акты п-п'!$C$5:$I$57,5,FALSE()) -> Чупин А.А. | X22: =поверки!$G22-поверки!$U22 -> 1 | Y22: =поверки!$V22-поверки!$G22 -> 2 | Z22: =CONCATENATE(поверки!$Q22," ",поверки!$S22," номер ",поверки!$H22) -> Датчик температуры 248 номер 02244851/03221643
B23: 29.04.2025 12:17 | C23: Проскурякова Елена Львовна | D23: ООО "РИ-ИНВЕСТ" | F23: 28033-05 | G23: 45749 | H23: 02299123/03251332 | J23: Опубликован | K23: Да | L23: С-ЕЖБ/02-04-2025/429422971 | N23: =IF(COUNTIF(поверки!$L$6:$L$3175,поверки!$L23)>1,"Дубликат","") | O23: 18 | P23: =CONCATENATE(TEXT(MONTH(поверки!$G23),"00"),"/",TEXT(поверки!$O23,"000"), "/",TEXT(YEAR(поверки!$G23)-2000,"00")) -> 04/018/25 | Q23: =VLOOKUP(поверки!$F23,'соответстиви ОТ типу'!$K$4:$M$344,2,FALSE()) -> Датчик температуры | R23: Кадыков П.Ю. | S23: 248 | T23: 1 | U23: =VLOOKUP(поверки!$T23,'Акты п-п'!$C$5:$I$57,2,FALSE()) -> 45748 | V23: =VLOOKUP(поверки!$T23,'Акты п-п'!$C$5:$I$57,3,FALSE()) -> 45751 | W23: =VLOOKUP(поверки!$T23,'Акты п-п'!$C$5:$I$57,5,FALSE()) -> Чупин А.А. | X23: =поверки!$G23-поверки!$U23 -> 1 | Y23: =поверки!$V23-поверки!$G23 -> 2 | Z23: =CONCATENATE(поверки!$Q23," ",поверки!$S23," номер ",поверки!$H23) -> Датчик температуры 248 номер 02299123/03251332
B24: 29.04.2025 12:17 | C24: Проскурякова Елена Львовна | D24: ООО "РИ-ИНВЕСТ" | F24: 57175-14 | G24: 45749 | H24: 3631-2-1 | J24: Опубликован | K24: Да | L24: С-ЕЖБ/02-04-2025/429422970 | N24: =IF(COUNTIF(поверки!$L$6:$L$3175,поверки!$L24)>1,"Дубликат","") | O24: 19 | P24: =CONCATENATE(TEXT(MONTH(поверки!$G24),"00"),"/",TEXT(поверки!$O24,"000"), "/",TEXT(YEAR(поверки!$G24)-2000,"00")) -> 04/019/25 | Q24: =VLOOKUP(поверки!$F24,'соответстиви ОТ типу'!$K$4:$M$344,2,FALSE()) -> Датчик температуры | R24: Кадыков П.Ю. | S24: ТСПТ 100-028 | T24: 1 | U24: =VLOOKUP(поверки!$T24,'Акты п-п'!$C$5:$I$57,2,FALSE()) -> 45748 | V24: =VLOOKUP(поверки!$T24,'Акты п-п'!$C$5:$I$57,3,FALSE()) -> 45751 | W24: =VLOOKUP(поверки!$T24,'Акты п-п'!$C$5:$I$57,5,FALSE()) -> Чупин А.А. | X24: =поверки!$G24-поверки!$U24 -> 1 | Y24: =поверки!$V24-поверки!$G24 -> 2 | Z24: =CONCATENATE(поверки!$Q24," ",поверки!$S24," номер ",поверки!$H24) -> Датчик температуры ТСПТ 100-028 номер 3631-2-1
B25: 29.04.2025 12:17 | C25: Проскурякова Елена Львовна | D25: ООО "РИ-ИНВЕСТ" | F25: 50958-12 | G25: 45749 | H25: 830430 | J25: Опубликован | K25: Да | L25: С-ЕЖБ/02-04-2025/429422968 | N25: =IF(COUNTIF(поверки!$L$6:$L$3175,поверки!$L25)>1,"Дубликат","") | O25: 20 | P25: =CONCATENATE(TEXT(MONTH(поверки!$G25),"00"),"/",TEXT(поверки!$O25,"000"), "/",TEXT(YEAR(поверки!$G25)-2000,"00")) -> 04/020/25 | Q25: =VLOOKUP(поверки!$F25,'соответстиви ОТ типу'!$K$4:$M$344,2,FALSE()) -> Преобразователь вторичный | R25: Кадыков П.Ю. | S25: T32.1S | T25: 1 | U25: =VLOOKUP(поверки!$T25,'Акты п-п'!$C$5:$I$57,2,FALSE()) -> 45748 | V25: =VLOOKUP(поверки!$T25,'Акты п-п'!$C$5:$I$57,3,FALSE()) -> 45751 | W25: =VLOOKUP(поверки!$T25,'Акты п-п'!$C$5:$I$57,5,FALSE()) -> Чупин А.А. | X25: =поверки!$G25-поверки!$U25 -> 1 | Y25: =поверки!$V25-поверки!$G25 -> 2 | Z25: =CONCATENATE(поверки!$Q25," ",поверки!$S25," номер ",поверки!$H25) -> Преобразователь вторичный T32.1S номер 830430
B26: 29.04.2025 12:17 | C26: Проскурякова Елена Львовна | D26: ООО "РИ-ИНВЕСТ" | F26: 47279-11 | G26: 45749 | H26: 1103TS56 | J26: Опубликован | K26: Да | L26: С-ЕЖБ/02-04-2025/429422966 | N26: =IF(COUNTIF(поверки!$L$6:$L$3175,поверки!$L26)>1,"Дубликат","") | O26: 21 | P26: =CONCATENATE(TEXT(MONTH(поверки!$G26),"00"),"/",TEXT(поверки!$O26,"000"), "/",TEXT(YEAR(поверки!$G26)-2000,"00")) -> 04/021/25 | Q26: =VLOOKUP(поверки!$F26,'соответстиви ОТ типу'!$K$4:$M$344,2,FALSE()) -> ТСП | R26: Кадыков П.Ю. | S26: TR55 | T26: 1 | U26: =VLOOKUP(поверки!$T26,'Акты п-п'!$C$5:$I$57,2,FALSE()) -> 45748 | V26: =VLOOKUP(поверки!$T26,'Акты п-п'!$C$5:$I$57,3,FALSE()) -> 45751 | W26: =VLOOKUP(поверки!$T26,'Акты п-п'!$C$5:$I$57,5,FALSE()) -> Чупин А.А. | X26: =поверки!$G26-поверки!$U26 -> 1 | Y26: =поверки!$V26-поверки!$G26 -> 2 | Z26: =CONCATENATE(поверки!$Q26," ",поверки!$S26," номер ",поверки!$H26) -> ТСП TR55 номер 1103TS56
B27: 29.04.2025 12:17 | C27: Проскурякова Елена Львовна | D27: ООО "РИ-ИНВЕСТ" | F27: 50958-12 | G27: 45749 | H27: 850017 | J27: Опубликован | K27: Да | L27: С-ЕЖБ/02-04-2025/429422965 | N27: =IF(COUNTIF(поверки!$L$6:$L$3175,поверки!$L27)>1,"Дубликат","") | O27: 22 | P27: =CONCATENATE(TEXT(MONTH(поверки!$G27),"00"),"/",TEXT(поверки!$O27,"000"), "/",TEXT(YEAR(поверки!$G27)-2000,"00")) -> 04/022/25 | Q27: =VLOOKUP(поверки!$F27,'соответстиви ОТ типу'!$K$4:$M$344,2,FALSE()) -> Преобразователь вторичный | R27: Кадыков П.Ю. | S27: T32.1S | T27: 1 | U27: =VLOOKUP(поверки!$T27,'Акты п-п'!$C$5:$I$57,2,FALSE()) -> 45748 | V27: =VLOOKUP(поверки!$T27,'Акты п-п'!$C$5:$I$57,3,FALSE()) -> 45751 | W27: =VLOOKUP(поверки!$T27,'Акты п-п'!$C$5:$I$57,5,FALSE()) -> Чупин А.А. | X27: =поверки!$G27-поверки!$U27 -> 1 | Y27: =поверки!$V27-поверки!$G27 -> 2 | Z27: =CONCATENATE(поверки!$Q27," ",поверки!$S27," номер ",поверки!$H27) -> Преобразователь вторичный T32.1S номер 850017
B28: 29.04.2025 12:17 | C28: Проскурякова Елена Львовна | D28: ООО "РИ-ИНВЕСТ" | F28: 47279-11 | G28: 45749 | H28: 1104F2G7 | J28: Опубликован | K28: Да | L28: С-ЕЖБ/02-04-2025/429422963 | N28: =IF(COUNTIF(поверки!$L$6:$L$3175,поверки!$L28)>1,"Дубликат","") | O28: 23 | P28: =CONCATENATE(TEXT(MONTH(поверки!$G28),"00"),"/",TEXT(поверки!$O28,"000"), "/",TEXT(YEAR(поверки!$G28)-2000,"00")) -> 04/023/25 | Q28: =VLOOKUP(поверки!$F28,'соответстиви ОТ типу'!$K$4:$M$344,2,FALSE()) -> ТСП | R28: Кадыков П.Ю. | S28: TR55 | T28: 1 | U28: =VLOOKUP(поверки!$T28,'Акты п-п'!$C$5:$I$57,2,FALSE()) -> 45748 | V28: =VLOOKUP(поверки!$T28,'Акты п-п'!$C$5:$I$57,3,FALSE()) -> 45751 | W28: =VLOOKUP(поверки!$T28,'Акты п-п'!$C$5:$I$57,5,FALSE()) -> Чупин А.А. | X28: =поверки!$G28-поверки!$U28 -> 1 | Y28: =поверки!$V28-поверки!$G28 -> 2 | Z28: =CONCATENATE(поверки!$Q28," ",поверки!$S28," номер ",поверки!$H28) -> ТСП TR55 номер 1104F2G7
B29: 29.04.2025 12:17 | C29: Проскурякова Елена Львовна | D29: ООО "РИ-ИНВЕСТ" | F29: 50958-12 | G29: 45749 | H29: 850370 | J29: Опубликован | K29: Да | L29: С-ЕЖБ/02-04-2025/429422962 | N29: =IF(COUNTIF(поверки!$L$6:$L$3175,поверки!$L29)>1,"Дубликат","") | O29: 24 | P29: =CONCATENATE(TEXT(MONTH(поверки!$G29),"00"),"/",TEXT(поверки!$O29,"000"), "/",TEXT(YEAR(поверки!$G29)-2000,"00")) -> 04/024/25 | Q29: =VLOOKUP(поверки!$F29,'соответстиви ОТ типу'!$K$4:$M$344,2,FALSE()) -> Преобразователь вторичный | R29: Кадыков П.Ю. | S29: T32.1S | T29: 1 | U29: =VLOOKUP(поверки!$T29,'Акты п-п'!$C$5:$I$57,2,FALSE()) -> 45748 | V29: =VLOOKUP(поверки!$T29,'Акты п-п'!$C$5:$I$57,3,FALSE()) -> 45751 | W29: =VLOOKUP(поверки!$T29,'Акты п-п'!$C$5:$I$57,5,FALSE()) -> Чупин А.А. | X29: =поверки!$G29-поверки!$U29 -> 1 | Y29: =поверки!$V29-поверки!$G29 -> 2 | Z29: =CONCATENATE(поверки!$Q29," ",поверки!$S29," номер ",поверки!$H29) -> Преобразователь вторичный T32.1S номер 850370
B30: 29.04.2025 12:17 | C30: Проскурякова Елена Львовна | D30: ООО "РИ-ИНВЕСТ" | F30: 47279-11 | G30: 45749 | H30: 1104F2G8 | J30: Опубликован | K30: Да | L30: С-ЕЖБ/02-04-2025/429422960 | N30: =IF(COUNTIF(поверки!$L$6:$L$3175,поверки!$L30)>1,"Дубликат","") | O30: 25 | P30: =CONCATENATE(TEXT(MONTH(поверки!$G30),"00"),"/",TEXT(поверки!$O30,"000"), "/",TEXT(YEAR(поверки!$G30)-2000,"00")) -> 04/025/25 | Q30: =VLOOKUP(поверки!$F30,'соответстиви ОТ типу'!$K$4:$M$344,2,FALSE()) -> ТСП | R30: Кадыков П.Ю. | S30: TR55 | T30: 1 | U30: =VLOOKUP(поверки!$T30,'Акты п-п'!$C$5:$I$57,2,FALSE()) -> 45748 | V30: =VLOOKUP(поверки!$T30,'Акты п-п'!$C$5:$I$57,3,FALSE()) -> 45751 | W30: =VLOOKUP(поверки!$T30,'Акты п-п'!$C$5:$I$57,5,FALSE()) -> Чупин А.А. | X30: =поверки!$G30-поверки!$U30 -> 1 | Y30: =поверки!$V30-поверки!$G30 -> 2 | Z30: =CONCATENATE(поверки!$Q30," ",поверки!$S30," номер ",поверки!$H30) -> ТСП TR55 номер 1104F2G8
B31: 29.04.2025 12:17 | C31: Проскурякова Елена Львовна | D31: ООО "РИ-ИНВЕСТ" | F31: 50138-12 | G31: 45749 | H31: J501701426C | J31: Опубликован | K31: Да | L31: С-ЕЖБ/02-04-2025/429422959 | N31: =IF(COUNTIF(поверки!$L$6:$L$3175,поверки!$L31)>1,"Дубликат","") | O31: 26 | P31: =CONCATENATE(TEXT(MONTH(поверки!$G31),"00"),"/",TEXT(поверки!$O31,"000"), "/",TEXT(YEAR(поверки!$G31)-2000,"00")) -> 04/026/25 | Q31: =VLOOKUP(поверки!$F31,'соответстиви ОТ типу'!$K$4:$M$344,2,FALSE()) -> Преобразователь измерительный | R31: Чупин А.А. | S31: iTEMP мод.TMT82 | T31: 1 | U31: =VLOOKUP(поверки!$T31,'Акты п-п'!$C$5:$I$57,2,FALSE()) -> 45748 | V31: =VLOOKUP(поверки!$T31,'Акты п-п'!$C$5:$I$57,3,FALSE()) -> 45751 | W31: =VLOOKUP(поверки!$T31,'Акты п-п'!$C$5:$I$57,5,FALSE()) -> Чупин А.А. | X31: =поверки!$G31-поверки!$U31 -> 1 | Y31: =поверки!$V31-поверки!$G31 -> 2 | Z31: =CONCATENATE(поверки!$Q31," ",поверки!$S31," номер ",поверки!$H31) -> Преобразователь измерительный iTEMP мод.TMT82 номер J501701426C
B32: 29.04.2025 12:17 | C32: Проскурякова Елена Львовна | D32: ООО "РИ-ИНВЕСТ" | F32: 49519-12 | G32: 45749 | H32: J500181430B | J32: Опубликован | K32: Да | L32: С-ЕЖБ/02-04-2025/429422957 | N32: =IF(COUNTIF(поверки!$L$6:$L$3175,поверки!$L32)>1,"Дубликат","") | O32: 27 | P32: =CONCATENATE(TEXT(MONTH(поверки!$G32),"00"),"/",TEXT(поверки!$O32,"000"), "/",TEXT(YEAR(поверки!$G32)-2000,"00")) -> 04/027/25 | Q32: =VLOOKUP(поверки!$F32,'соответстиви ОТ типу'!$K$4:$M$344,2,FALSE()) -> ТСП | R32: Чупин А.А. | S32: TR65 | T32: 1 | U32: =VLOOKUP(поверки!$T32,'Акты п-п'!$C$5:$I$57,2,FALSE()) -> 45748 | V32: =VLOOKUP(поверки!$T32,'Акты п-п'!$C$5:$I$57,3,FALSE()) -> 45751 | W32: =VLOOKUP(поверки!$T32,'Акты п-п'!$C$5:$I$57,5,FALSE()) -> Чупин А.А. | X32: =поверки!$G32-поверки!$U32 -> 1 | Y32: =поверки!$V32-поверки!$G32 -> 2 | Z32: =CONCATENATE(поверки!$Q32," ",поверки!$S32," номер ",поверки!$H32) -> ТСП TR65 номер J500181430B
B33: 29.04.2025 12:17 | C33: Проскурякова Елена Львовна | D33: ООО "РИ-ИНВЕСТ" | F33: 50138-12 | G33: 45749 | H33: J5016F1426C | J33: Опубликован | K33: Да | L33: С-ЕЖБ/02-04-2025/429422956 | N33: =IF(COUNTIF(поверки!$L$6:$L$3175,поверки!$L33)>1,"Дубликат","") | O33: 28 | P33: =CONCATENATE(TEXT(MONTH(поверки!$G33),"00"),"/",TEXT(поверки!$O33,"000"), "/",TEXT(YEAR(поверки!$G33)-2000,"00")) -> 04/028/25 | Q33: =VLOOKUP(поверки!$F33,'соответстиви ОТ типу'!$K$4:$M$344,2,FALSE()) -> Преобразователь измерительный | R33: Чупин А.А. | S33: iTEMP мод.TMT82 | T33: 1 | U33: =VLOOKUP(поверки!$T33,'Акты п-п'!$C$5:$I$57,2,FALSE()) -> 45748 | V33: =VLOOKUP(поверки!$T33,'Акты п-п'!$C$5:$I$57,3,FALSE()) -> 45751 | W33: =VLOOKUP(поверки!$T33,'Акты п-п'!$C$5:$I$57,5,FALSE()) -> Чупин А.А. | X33: =поверки!$G33-поверки!$U33 -> 1 | Y33: =поверки!$V33-поверки!$G33 -> 2 | Z33: =CONCATENATE(поверки!$Q33," ",поверки!$S33," номер ",поверки!$H33) -> Преобразователь измерительный iTEMP мод.TMT82 номер J5016F1426C
B34: 29.04.2025 12:17 | C34: Проскурякова Елена Львовна | D34: ООО "РИ-ИНВЕСТ" | F34: 49519-12 | G34: 45749 | H34: J500141430B | J34: Опубликован | K34: Да | L34: С-ЕЖБ/02-04-2025/429422954 | N34: =IF(COUNTIF(поверки!$L$6:$L$3175,поверки!$L34)>1,"Дубликат","") | O34: 29 | P34: =CONCATENATE(TEXT(MONTH(поверки!$G34),"00"),"/",TEXT(поверки!$O34,"000"), "/",TEXT(YEAR(поверки!$G34)-2000,"00")) -> 04/029/25 | Q34: =VLOOKUP(поверки!$F34,'соответстиви ОТ типу'!$K$4:$M$344,2,FALSE()) -> ТСП | R34: Чупин А.А. | S34: TR65 | T34: 1 | U34: =VLOOKUP(поверки!$T34,'Акты п-п'!$C$5:$I$57,2,FALSE()) -> 45748 | V34: =VLOOKUP(поверки!$T34,'Акты п-п'!$C$5:$I$57,3,FALSE()) -> 45751 | W34: =VLOOKUP(поверки!$T34,'Акты п-п'!$C$5:$I$57,5,FALSE()) -> Чупин А.А. | X34: =поверки!$G34-поверки!$U34 -> 1 | Y34: =поверки!$V34-поверки!$G34 -> 2 | Z34: =CONCATENATE(поверки!$Q34," ",поверки!$S34," номер ",поверки!$H34) -> ТСП TR65 номер J500141430B
B35: 29.04.2025 12:17 | C35: Проскурякова Елена Львовна | D35: ООО "РИ-ИНВЕСТ" | F35: 50138-12 | G35: 45749 | H35: J5016D1426C | J35: Опубликован | K35: Да | L35: С-ЕЖБ/02-04-2025/429422953 | N35: =IF(COUNTIF(поверки!$L$6:$L$3175,поверки!$L35)>1,"Дубликат","") | O35: 30 | P35: =CONCATENATE(TEXT(MONTH(поверки!$G35),"00"),"/",TEXT(поверки!$O35,"000"), "/",TEXT(YEAR(поверки!$G35)-2000,"00")) -> 04/030/25 | Q35: =VLOOKUP(поверки!$F35,'соответстиви ОТ типу'!$K$4:$M$344,2,FALSE()) -> Преобразователь измерительный | R35: Чупин А.А. | S35: iTEMP мод.TMT82 | T35: 1 | U35: =VLOOKUP(поверки!$T35,'Акты п-п'!$C$5:$I$57,2,FALSE()) -> 45748 | V35: =VLOOKUP(поверки!$T35,'Акты п-п'!$C$5:$I$57,3,FALSE()) -> 45751 | W35: =VLOOKUP(поверки!$T35,'Акты п-п'!$C$5:$I$57,5,FALSE()) -> Чупин А.А. | X35: =поверки!$G35-поверки!$U35 -> 1 | Y35: =поверки!$V35-поверки!$G35 -> 2 | Z35: =CONCATENATE(поверки!$Q35," ",поверки!$S35," номер ",поверки!$H35) -> Преобразователь измерительный iTEMP мод.TMT82 номер J5016D1426C
... B42: 29.04.2025 12:17 | C42: Проскурякова Елена Львовна | D42: ООО "РИ-ИНВЕСТ" | F42: 26239-06 | G42: 45749 | H42: D70041142FC | J42: Опубликован | K42: Да | L42: С-ЕЖБ/02-04-2025/429422942 | N42: =IF(COUNTIF(поверки!$L$6:$L$3175,поверки!$L42)>1,"Дубликат","") | O42: 37 | P42: =CONCATENATE(TEXT(MONTH(поверки!$G42),"00"),"/",TEXT(поверки!$O42,"000"), "/",TEXT(YEAR(поверки!$G42)-2000,"00")) -> 04/037/25 | Q42: =VLOOKUP(поверки!$F42,'соответстиви ОТ типу'!$K$4:$M$344,2,FALSE()) -> ТСП | R42: Чупин А.А. | S42: TR61 | T42: 1 | U42: =VLOOKUP(поверки!$T42,'Акты п-п'!$C$5:$I$57,2,FALSE()) -> 45748 | V42: =VLOOKUP(поверки!$T42,'Акты п-п'!$C$5:$I$57,3,FALSE()) -> 45751 | W42: =VLOOKUP(поверки!$T42,'Акты п-п'!$C$5:$I$57,5,FALSE()) -> Чупин А.А. | X42: =поверки!$G42-поверки!$U42 -> 1 | Y42: =поверки!$V42-поверки!$G42 -> 2 | Z42: =CONCATENATE(поверки!$Q42," ",поверки!$S42," номер ",поверки!$H42) -> ТСП TR61 номер D70041142FC
B43: 29.04.2025 12:17 | C43: Проскурякова Елена Львовна | D43: ООО "РИ-ИНВЕСТ" | F43: 48988-12 | G43: 45749 | H43: 09904095 | J43: Опубликован | K43: Да | L43: С-ЕЖБ/02-04-2025/429422940 | N43: =IF(COUNTIF(поверки!$L$6:$L$3175,поверки!$L43)>1,"Дубликат","") | O43: 38 | P43: =CONCATENATE(TEXT(MONTH(поверки!$G43),"00"),"/",TEXT(поверки!$O43,"000"), "/",TEXT(YEAR(поверки!$G43)-2000,"00")) -> 04/038/25 | Q43: =VLOOKUP(поверки!$F43,'соответстиви ОТ типу'!$K$4:$M$344,2,FALSE()) -> Преобразователь измерительный | R43: Чупин А.А. | S43: 248 | T43: 1 | U43: =VLOOKUP(поверки!$T43,'Акты п-п'!$C$5:$I$57,2,FALSE()) -> 45748 | V43: =VLOOKUP(поверки!$T43,'Акты п-п'!$C$5:$I$57,3,FALSE()) -> 45751 | W43: =VLOOKUP(поверки!$T43,'Акты п-п'!$C$5:$I$57,5,FALSE()) -> Чупин А.А. | X43: =поверки!$G43-поверки!$U43 -> 1 | Y43: =поверки!$V43-поверки!$G43 -> 2 | Z43: =CONCATENATE(поверки!$Q43," ",поверки!$S43," номер ",поверки!$H43) -> Преобразователь измерительный 248 номер 09904095
B44: 29.04.2025 12:17 | C44: Проскурякова Елена Львовна | D44: ООО "РИ-ИНВЕСТ" | F44: 58808-14 | G44: 45749 | H44: 7397 | J44: Опубликован | K44: Да | L44: С-ЕЖБ/02-04-2025/429422939 | N44: =IF(COUNTIF(поверки!$L$6:$L$3175,поверки!$L44)>1,"Дубликат","") | O44: 39 | P44: =CONCATENATE(TEXT(MONTH(поверки!$G44),"00"),"/",TEXT(поверки!$O44,"000"), "/",TEXT(YEAR(поверки!$G44)-2000,"00")) -> 04/039/25 | Q44: =VLOOKUP(поверки!$F44,'соответстиви ОТ типу'!$K$4:$M$344,2,FALSE()) -> ТСП | R44: Чупин А.А. | S44: ТС-1088/1 | T44: 1 | U44: =VLOOKUP(поверки!$T44,'Акты п-п'!$C$5:$I$57,2,FALSE()) -> 45748 | V44: =VLOOKUP(поверки!$T44,'Акты п-п'!$C$5:$I$57,3,FALSE()) -> 45751 | W44: =VLOOKUP(поверки!$T44,'Акты п-п'!$C$5:$I$57,5,FALSE()) -> Чупин А.А. | X44: =поверки!$G44-поверки!$U44 -> 1 | Y44: =поверки!$V44-поверки!$G44 -> 2 | Z44: =CONCATENATE(поверки!$Q44," ",поверки!$S44," номер ",поверки!$H44) -> ТСП ТС-1088/1 номер 7397
B45: 29.04.2025 12:17 | C45: Проскурякова Елена Львовна | D45: ООО "РИ-ИНВЕСТ" | F45: 49519-12 | G45: 45749 | H45: H9027514150 | J45: Опубликован | K45: Да | L45: С-ЕЖБ/02-04-2025/429422938 | M45: =IF(COUNTIF(поверки!$H$6:$H$3175,поверки!$H45)>1,"Дубликат","") | N45: =IF(COUNTIF(поверки!$L$6:$L$3175,поверки!$L45)>1,"Дубликат","") | O45: 40 | P45: =CONCATENATE(TEXT(MONTH(поверки!$G45),"00"),"/",TEXT(поверки!$O45,"000"), "/",TEXT(YEAR(поверки!$G45)-2000,"00")) -> 04/040/25 | Q45: =VLOOKUP(поверки!$F45,'соответстиви ОТ типу'!$K$4:$M$344,2,FALSE()) -> ТСП | R45: Чупин А.А. | S45: TR24 | T45: 1 | U45: =VLOOKUP(поверки!$T45,'Акты п-п'!$C$5:$I$57,2,FALSE()) -> 45748 | V45: =VLOOKUP(поверки!$T45,'Акты п-п'!$C$5:$I$57,3,FALSE()) -> 45751 | W45: =VLOOKUP(поверки!$T45,'Акты п-п'!$C$5:$I$57,5,FALSE()) -> Чупин А.А. | X45: =поверки!$G45-поверки!$U45 -> 1 | Y45: =поверки!$V45-поверки!$G45 -> 2 | Z45: =CONCATENATE(поверки!$Q45," ",поверки!$S45," номер ",поверки!$H45) -> ТСП TR24 номер H9027514150
B46: 29.04.2025 12:17 | C46: Проскурякова Елена Львовна | D46: ООО "РИ-ИНВЕСТ" | F46: 49519-12 | G46: 45749 | H46: H9026814150 | J46: Опубликован | K46: Да | L46: С-ЕЖБ/02-04-2025/429422936 | M46: =IF(COUNTIF(поверки!$H$6:$H$3175,поверки!$H46)>1,"Дубликат","") | N46: =IF(COUNTIF(поверки!$L$6:$L$3175,поверки!$L46)>1,"Дубликат","") | O46: 41 | P46: =CONCATENATE(TEXT(MONTH(поверки!$G46),"00"),"/",TEXT(поверки!$O46,"000"), "/",TEXT(YEAR(поверки!$G46)-2000,"00")) -> 04/041/25 | Q46: =VLOOKUP(поверки!$F46,'соответстиви ОТ типу'!$K$4:$M$344,2,FALSE()) -> ТСП | R46: Чупин А.А. | S46: TR24 | T46: 1 | U46: =VLOOKUP(поверки!$T46,'Акты п-п'!$C$5:$I$57,2,FALSE()) -> 45748 | V46: =VLOOKUP(поверки!$T46,'Акты п-п'!$C$5:$I$57,3,FALSE()) -> 45751 | W46: =VLOOKUP(поверки!$T46,'Акты п-п'!$C$5:$I$57,5,FALSE()) -> Чупин А.А. | X46: =поверки!$G46-поверки!$U46 -> 1 | Y46: =поверки!$V46-поверки!$G46 -> 2 | Z46: =CONCATENATE(поверки!$Q46," ",поверки!$S46," номер ",поверки!$H46) -> ТСП TR24 номер H9026814150
B47: 29.04.2025 12:17 | C47: Проскурякова Елена Львовна | D47: ООО "РИ-ИНВЕСТ" | F47: 22257-05 | G47: 45749 | H47: 3175053 | J47: Опубликован | K47: Да | L47: С-ЕЖБ/02-04-2025/429422935 | M47: =IF(COUNTIF(поверки!$H$6:$H$3175,поверки!$H47)>1,"Дубликат","") | N47: =IF(COUNTIF(поверки!$L$6:$L$3175,поверки!$L47)>1,"Дубликат","") | O47: 42 | P47: =CONCATENATE(TEXT(MONTH(поверки!$G47),"00"),"/",TEXT(поверки!$O47,"000"), "/",TEXT(YEAR(поверки!$G47)-2000,"00")) -> 04/042/25 | Q47: =VLOOKUP(поверки!$F47,'соответстиви ОТ типу'!$K$4:$M$344,2,FALSE()) -> ТСП | R47: Чупин А.А. | S47: серии 65 | T47: 1 | U47: =VLOOKUP(поверки!$T47,'Акты п-п'!$C$5:$I$57,2,FALSE()) -> 45748 | V47: =VLOOKUP(поверки!$T47,'Акты п-п'!$C$5:$I$57,3,FALSE()) -> 45751 | W47: =VLOOKUP(поверки!$T47,'Акты п-п'!$C$5:$I$57,5,FALSE()) -> Чупин А.А. | X47: =поверки!$G47-поверки!$U47 -> 1 | Y47: =поверки!$V47-поверки!$G47 -> 2 | Z47: =CONCATENATE(поверки!$Q47," ",поверки!$S47," номер ",поверки!$H47) -> ТСП серии 65 номер 3175053
B48: 29.04.2025 12:17 | C48: Проскурякова Елена Львовна | D48: ООО "РИ-ИНВЕСТ" | F48: 50138-12 | G48: 45749 | H48: F602430426C | J48: Опубликован | K48: Да | L48: С-ЕЖБ/02-04-2025/429422933 | M48: =IF(COUNTIF(поверки!$H$6:$H$3175,поверки!$H48)>1,"Дубликат","") | N48: =IF(COUNTIF(поверки!$L$6:$L$3175,поверки!$L48)>1,"Дубликат","") | O48: 43 | P48: =CONCATENATE(TEXT(MONTH(поверки!$G48),"00"),"/",TEXT(поверки!$O48,"000"), "/",TEXT(YEAR(поверки!$G48)-2000,"00")) -> 04/043/25 | Q48: =VLOOKUP(поверки!$F48,'соответстиви ОТ типу'!$K$4:$M$344,2,FALSE()) -> Преобразователь измерительный | R48: Чупин А.А. | S48: iTEMP мод.TMT82 | T48: 1 | U48: =VLOOKUP(поверки!$T48,'Акты п-п'!$C$5:$I$57,2,FALSE()) -> 45748 | V48: =VLOOKUP(поверки!$T48,'Акты п-п'!$C$5:$I$57,3,FALSE()) -> 45751 | W48: =VLOOKUP(поверки!$T48,'Акты п-п'!$C$5:$I$57,5,FALSE()) -> Чупин А.А. | X48: =поверки!$G48-поверки!$U48 -> 1 | Y48: =поверки!$V48-поверки!$G48 -> 2 | Z48: =CONCATENATE(поверки!$Q48," ",поверки!$S48," номер ",поверки!$H48) -> Преобразователь измерительный iTEMP мод.TMT82 номер F602430426C
...

Sheet Акты п-п
C4: № акта | D4: Дата приемки | E4: Дата выдачи | F4: Заказчик | G4: Поверитель | H4: Столбец1 | I4: ФизЛицоЗаказчик
C5: 1 | D5: 45748 | E5: 45751 | F5: ООО "РИ-ИНВЕСТ" | G5: Чупин А.А. | H5: ='Акты п-п'!$E5-'Акты п-п'!$D5 -> 3 | I5: Астахов Е.А.
C6: 2 | D6: 45748 | E6: 45754 | F6: ООО «ГАЗПРОМНЕФТЬ-ЯМАЛ» | G6: Манджеев А.А. | H6: ='Акты п-п'!$E6-'Акты п-п'!$D6 -> 6 | I6: Попов Е.В.
C7: 3 | D7: 45754 | E7: 45758 | F7: ООО "РИ-ИНВЕСТ" | G7: Большаков С.Н. | H7: ='Акты п-п'!$E7-'Акты п-п'!$D7 -> 4 | I7: Астахов Е.А.
C8: 4 | D8: 45755 | E8: 45757 | F8: ООО «ГАЗПРОМНЕФТЬ-ЯМАЛ» | G8: Манджеев А.А. | H8: ='Акты п-п'!$E8-'Акты п-п'!$D8 -> 2 | I8: Попов Е.В.
C9: 5 | D9: 45761 | E9: 45765 | F9: ООО "РИ-ИНВЕСТ" | G9: Кадыков П.Ю. | H9: ='Акты п-п'!$E9-'Акты п-п'!$D9 -> 4 | I9: Астахов Е.А.
C10: 6 | D10: 45759 | E10: 45761 | F10: ООО «ГАЗПРОМНЕФТЬ-ЯМАЛ» | G10: Манджеев А.А. | H10: ='Акты п-п'!$E10-'Акты п-п'!$D10 -> 2 | I10: Попов Е.В.
C11: 7 | D11: 45768 | E11: 45772 | F11: ООО "РИ-ИНВЕСТ" | G11: Кадыков П.Ю. | H11: ='Акты п-п'!$E11-'Акты п-п'!$D11 -> 4 | I11: Астахов Е.А.
C12: 8 | D12: 45767 | E12: 45770 | F12: ООО «ГАЗПРОМНЕФТЬ-ЯМАЛ» | G12: Чупин А.А. | H12: ='Акты п-п'!$E12-'Акты п-п'!$D12 -> 3 | I12: Попов Е.В.
C13: 9 | D13: 45775 | E13: 45777 | F13: ООО "РИ-ИНВЕСТ" | G13: Запевахин Т.Е. | H13: ='Акты п-п'!$E13-'Акты п-п'!$D13 -> 2 | I13: Астахов Е.А.
C14: 10 | D14: 45776 | E14: 45777 | F14: ООО «ГАЗПРОМНЕФТЬ-ЯМАЛ» | G14: Кадыков П.Ю. | H14: ='Акты п-п'!$E14-'Акты п-п'!$D14 -> 1 | I14: Попов Е.В.
C15: 11 | H15: ='Акты п-п'!$E15-'Акты п-п'!$D15 -> 0
C16: 12 | H16: ='Акты п-п'!$E16-'Акты п-п'!$D16 -> 0
C17: 13 | H17: ='Акты п-п'!$E17-'Акты п-п'!$D17 -> 0
C18: 14 | H18: ='Акты п-п'!$E18-'Акты п-п'!$D18 -> 0
C19: 15 | H19: ='Акты п-п'!$E19-'Акты п-п'!$D19 -> 0
C20: 16 | H20: ='Акты п-п'!$E20-'Акты п-п'!$D20 -> 0
C21: 17 | H21: ='Акты п-п'!$E21-'Акты п-п'!$D21 -> 0
C22: 18 | H22: ='Акты п-п'!$E22-'Акты п-п'!$D22 -> 0
C23: 19 | H23: ='Акты п-п'!$E23-'Акты п-п'!$D23 -> 0
C24: 20 | H24: ='Акты п-п'!$E24-'Акты п-п'!$D24 -> 0
C25: 21 | H25: ='Акты п-п'!$E25-'Акты п-п'!$D25 -> 0
C26: 22 | H26: ='Акты п-п'!$E26-'Акты п-п'!$D26 -> 0
... C45: 41 | H45: ='Акты п-п'!$E45-'Акты п-п'!$D45 -> 0
B46: Октябрь | C46: 42 | G46: Большаков С.Н. | H46: ='Акты п-п'!$E46-'Акты п-п'!$D46 -> 0 | L46: Запевахин
C47: 43 | G47: Кадыков П.Ю | H47: ='Акты п-п'!$E47-'Акты п-п'!$D47 -> 0 | L47: Манджеев
C48: 44 | G48: Чупин А.А. | H48: ='Акты п-п'!$E48-'Акты п-п'!$D48 -> 0
C49: 45 | G49: Манджеев А.А. | H49: ='Акты п-п'!$E49-'Акты п-п'!$D49 -> 0 | L49: Запевахин
C50: 46 | G50: Большаков С.Н. | H50: ='Акты п-п'!$E50-'Акты п-п'!$D50 -> 0
B51: ноябрь | C51: 47 | H51: ='Акты п-п'!$E51-'Акты п-п'!$D51 -> 0
C52: 48 | H52: ='Акты п-п'!$E52-'Акты п-п'!$D52 -> 0
C53: 49 | H53: ='Акты п-п'!$E53-'Акты п-п'!$D53 -> 0
C54: 50 | H54: ='Акты п-п'!$E54-'Акты п-п'!$D54 -> 0
B55: декабрь | C55: 51 | G55: Запевахин Т.Е. | H55: ='Акты п-п'!$E55-'Акты п-п'!$D55 -> 0
C56: 52 | G56: Манджеев А.А. | H56: ='Акты п-п'!$E56-'Акты п-п'!$D56 -> 0
C57: 53 | G57: Чупин А.А. | H57: ='Акты п-п'!$E57-'Акты п-п'!$D57 -> 0

Sheet 1
B1: Номер акта | D1: 1
B2: дата
B3: приемки | C3: =VLOOKUP(D1,'Акты п-п'!$C$5:$I$57,2) -> 45748
B4: выдачи | C4: =VLOOKUP(D1,'Акты п-п'!$C$5:$I$57,3) -> 45751
C5: =VLOOKUP(D1,'Акты п-п'!$C$5:$I$57,5) -> Чупин А.А.
C6: Астахов Е.А.
C7: =VLOOKUP(D1,'Акты п-п'!$C$5:$I$57,4) -> ООО "РИ-ИНВЕСТ"
B9: АКТ | M9: АКТ
B10: приема-передачи СИ | M10: приема-передачи СИ
B12: =CONCATENATE("Мы, нижеподписавшиеся, представитель ",C7," , и представитель ООО «МКАИР», ") -> Мы, нижеподписавшиеся, представитель ООО "РИ-ИНВЕСТ" , и представитель ООО «МКАИР», | M12: =B12 -> Мы, нижеподписавшиеся, представитель ООО "РИ-ИНВЕСТ" , и представитель ООО «МКАИР»,
B13: =CONCATENATE("составили настоящий акт о том, что ",TEXT(C3,"ДД.ММ.ГГГГ"), " сданы в поверку следующие средства измерений:") -> составили настоящий акт о том, что 01.04.2025 сданы в поверку следующие средства измерений: | M13: =CONCATENATE("составили настоящий акт о том, что ",TEXT(C4,"ДД.ММ.ГГГГ"), " выданы с поверки следующие средства измерений:") -> составили настоящий акт о том, что 04.04.2025 выданы с поверки следующие средства измерений:
B15: 1 | C15: Контроллер Simatic S7-200 номер 205/M/S7-200 | M15: 1 | N15: =C15 -> Контроллер Simatic S7-200 номер 205/M/S7-200
B16: 2 | C16: Контроллер Simatic S7-300 номер 205/BMS01/S7-300 | M16: 2 | N16: =C16 -> Контроллер Simatic S7-300 номер 205/BMS01/S7-300
B17: 3 | C17: Контроллер Simatic S7-300 номер 205/BMS02/S7-300 | M17: 3 | N17: =C17 -> Контроллер Simatic S7-300 номер 205/BMS02/S7-300
B18: 4 | C18: Преобразователь давления EJX 530A номер 91R808434 | M18: 4 | N18: =C18 -> Преобразователь давления EJX 530A номер 91R808434
B19: 5 | C19: Датчик температуры Метран-286-02 номер 2080951 | M19: 5 | N19: =C19 -> Датчик температуры Метран-286-02 номер 2080951
B20: 6 | C20: Датчик температуры ТПУ 0304Ех номер 12-9083 | M20: 6 | N20: =C20 -> Датчик температуры ТПУ 0304Ех номер 12-9083
B21: 7 | C21: Датчик температуры ТПУ 0304Ех номер 12-9082 | M21: 7 | N21: =C21 -> Датчик температуры ТПУ 0304Ех номер 12-9082
B22: 8 | C22: Датчик температуры ТПУ 0304Ех номер 12-9078 | M22: 8 | N22: =C22 -> Датчик температуры ТПУ 0304Ех номер 12-9078
B23: 9 | C23: Датчик температуры ТПУ 0304Ех номер 12-9086 | M23: 9 | N23: =C23 -> Датчик температуры ТПУ 0304Ех номер 12-9086
B24: 10 | C24: Датчик температуры ТПУ 0304Ех номер 12-9089 | M24: 10 | N24: =C24 -> Датчик температуры ТПУ 0304Ех номер 12-9089
B25: 11 | C25: Датчик температуры ТПУ 0304Ех номер 12-9079 | M25: 11 | N25: =C25 -> Датчик температуры ТПУ 0304Ех номер 12-9079
B26: 12 | C26: Датчик температуры 248 номер 02244553/03221492 | M26: 12 | N26: =C26 -> Датчик температуры 248 номер 02244553/03221492
... B246: 232 | C246: Манометр 213.53.063 номер 05171 | M246: 232 | N246: =C246 -> Манометр 213.53.063 номер 05171
B247: 233 | M247: 233 | N247: =C247 -> 0
B248: 234 | M248: 234 | N248: =C248 -> 0
B249: 235 | M249: 235 | N249: =C249 -> 0
B250: 236 | M250: 236 | N250: =C250 -> 0
B251: 237 | M251: 237 | N251: =C251 -> 0
B252: 238 | M252: 238 | N252: =C252 -> 0
B253: 239 | M253: 239 | N253: =C253 -> 0
B254: 240 | M254: 240 | N254: =C254 -> 0
B255: 241 | M255: 241 | N255: =C255 -> 0
B256: 242 | M256: 242 | N256: =C256 -> 0
B257: 243 | M257: 243 | N257: =C257 -> 0
B258: 244 | M258: 244 | N258: =C258 -> 0
... B414: 400 | M414: 400 | N414: =C414 -> 0
B416: =CONCATENATE("Принял представитель ООО ""МКАИР"" ",C5) -> Принял представитель ООО "МКАИР" Чупин А.А. | J416: =C3 -> 45748 | M416: =CONCATENATE("Сдал представитель ООО ""МКАИР"" ",C5) -> Сдал представитель ООО "МКАИР" Чупин А.А. | Q416: =C4 -> 45751
B417: Должность, Ф. И.О., подпись | M417: Должность, Ф. И.О., подпись
B419: =CONCATENATE("Сдал представитель ",C7," ",C6) -> Сдал представитель ООО "РИ-ИНВЕСТ" Астахов Е.А. | J419: =J416 -> 45748 | M419: =CONCATENATE("Принял представитель ", C7," ",,C6) -> Принял представитель ООО "РИ-ИНВЕСТ" Астахов Е.А. | Q419: =Q416 -> 45751
...

Sheet 2
B1: Номер акта | D1: 2
B2: дата
B3: приемки | C3: =VLOOKUP(D1,'Акты п-п'!$C$5:$I$57,2) -> 45748
B4: выдачи | C4: =VLOOKUP(D1,'Акты п-п'!$C$5:$I$57,3) -> 45754
C5: =VLOOKUP(D1,'Акты п-п'!$C$5:$I$57,5) -> Манджеев А.А.
C6: =VLOOKUP(D1,'Акты п-п'!$C$5:$I$57,7) -> Попов Е.В.
C7: =VLOOKUP(D1,'Акты п-п'!$C$5:$I$57,4) -> ООО «ГАЗПРОМНЕФТЬ-ЯМАЛ»
B9: АКТ | M9: АКТ
B10: приема-передачи СИ | M10: приема-передачи СИ
B12: =CONCATENATE("Мы, нижеподписавшиеся, представитель ",C7," , и представитель ООО «МКАИР», ") -> Мы, нижеподписавшиеся, представитель ООО «ГАЗПРОМНЕФТЬ-ЯМАЛ» , и представитель ООО «МКАИР», | M12: =B12 -> Мы, нижеподписавшиеся, представитель ООО «ГАЗПРОМНЕФТЬ-ЯМАЛ» , и представитель ООО «МКАИР»,
B13: =CONCATENATE("составили настоящий акт о том, что ",TEXT(C3,"ДД.ММ.ГГГГ"), " сданы в поверку следующие средства измерений:") -> составили настоящий акт о том, что 01.04.2025 сданы в поверку следующие средства измерений: | M13: =CONCATENATE("составили настоящий акт о том, что ",TEXT(C4,"ДД.ММ.ГГГГ"), " выданы с поверки следующие средства измерений:") -> составили настоящий акт о том, что 07.04.2025 выданы с поверки следующие средства измерений:
B15: 1 | C15: Газоанализатор ЭРИС-ОПТИМА ПЛЮС ЭРИС-ОПТИМА ПЛЮС М номер ER150099 | M15: 1 | N15: =C15 -> Газоанализатор ЭРИС-ОПТИМА ПЛЮС ЭРИС-ОПТИМА ПЛЮС М номер ER150099
B16: 2 | C16: Датчик горючих газов Searchpoint Optima Plus XTC номер Z0182517390061 | M16: 2 | N16: =C16 -> Датчик горючих газов Searchpoint Optima Plus XTC номер Z0182517390061
B17: 3 | C17: Датчик горючих газов Searchpoint Optima Plus XTC номер Z0182517390036 | M17: 3 | N17: =C17 -> Датчик горючих газов Searchpoint Optima Plus XTC номер Z0182517390036
B18: 4 | C18: Манометр ФТ МП4-Уф БС УХЛ1 номер В0124887 | M18: 4 | N18: =C18 -> Манометр ФТ МП4-Уф БС УХЛ1 номер В0124887
B19: 5 | C19: Манометр ФТ МП4-Уф БС УХЛ1 номер 9002257 | M19: 5 | N19: =C19 -> Манометр ФТ МП4-Уф БС УХЛ1 номер 9002257
B20: 6 | C20: Манометр ФТ МП4-Уф БС УХЛ1 номер 9001651 | M20: 6 | N20: =C20 -> Манометр ФТ МП4-Уф БС УХЛ1 номер 9001651
B21: 7 | C21: Манометр ФТ МП4-Уф номер 001978 | M21: 7 | N21: =C21 -> Манометр ФТ МП4-Уф номер 001978
B22: 8 | C22: Манометр ТМ серия 10 номер 10486 | M22: 8 | N22: =C22 -> Манометр ТМ серия 10 номер 10486
B23: 9 | C23: Манометр ТМ серия 20 номер 10540 | M23: 9 | N23: =C23 -> Манометр ТМ серия 20 номер 10540
B24: 10 | C24: Манометр ТМ серия 20 номер 3027528 | M24: 10 | N24: =C24 -> Манометр ТМ серия 20 номер 3027528
B25: 11 | C25: Манометр ТМ серия 20 номер 3027526 | M25: 11 | N25: =C25 -> Манометр ТМ серия 20 номер 3027526
B26: 12 | C26: Манометр ТМ серия 20 номер 3027527 | M26: 12 | N26: =C26 -> Манометр ТМ серия 20 номер 3027527
... B503: 489 | C503: Манометр ФТ ДМ8008-Вуф исп.2 номер 1008269 | M503: 489 | N503: =C503 -> Манометр ФТ ДМ8008-Вуф исп.2 номер 1008269
B504: 490 | M504: 490 | N504: =C504 -> 0
B505: 491 | M505: 491 | N505: =C505 -> 0
B506: 492 | M506: 492 | N506: =C506 -> 0
B507: 493 | M507: 493 | N507: =C507 -> 0
B508: 494 | M508: 494 | N508: =C508 -> 0
B509: 495 | M509: 495 | N509: =C509 -> 0
B510: 496 | M510: 496 | N510: =C510 -> 0
B511: 497 | M511: 497 | N511: =C511 -> 0
B512: 498 | M512: 498 | N512: =C512 -> 0
B513: 499 | M513: 499 | N513: =C513 -> 0
B514: 500 | M514: 500 | N514: =C514 -> 0
B515: 501 | M515: 501 | N515: =C515 -> 0
... B938: 924 | M938: 924 | N938: =C938 -> 0
B940: =CONCATENATE("Принял представитель ООО ""МКАИР"" ",C5) -> Принял представитель ООО "МКАИР" Манджеев А.А. | J940: =C3 -> 45748 | M940: =CONCATENATE("Сдал представитель ООО ""МКАИР"" ",C5) -> Сдал представитель ООО "МКАИР" Манджеев А.А. | Q940: =C4 -> 45754
B941: Должность, Ф. И.О., подпись | M941: Должность, Ф. И.О., подпись
B943: =CONCATENATE("Сдал представитель ",C7," ",C6) -> Сдал представитель ООО «ГАЗПРОМНЕФТЬ-ЯМАЛ» Попов Е.В. | J943: =J940 -> 45748 | M943: =CONCATENATE("Принял представитель ", C7," ",,C6) -> Принял представитель ООО «ГАЗПРОМНЕФТЬ-ЯМАЛ» Попов Е.В. | Q943: =Q940 -> 45754
...

Sheet 3
B1: Номер акта | D1: 3
B2: дата
B3: приемки | C3: =VLOOKUP(D1,'Акты п-п'!$C$5:$I$57,2) -> 45754
B4: выдачи | C4: =VLOOKUP(D1,'Акты п-п'!$C$5:$I$57,3) -> 45758
C5: =VLOOKUP(D1,'Акты п-п'!$C$5:$I$57,5) -> Большаков С.Н.
C6: Астахов Е.А.
C7: =VLOOKUP(D1,'Акты п-п'!$C$5:$I$57,4) -> ООО "РИ-ИНВЕСТ"
B9: АКТ | M9: АКТ
B10: приема-передачи СИ | M10: приема-передачи СИ
B12: =CONCATENATE("Мы, нижеподписавшиеся, представитель ",C7," , и представитель ООО «МКАИР», ") -> Мы, нижеподписавшиеся, представитель ООО "РИ-ИНВЕСТ" , и представитель ООО «МКАИР», | M12: =B12 -> Мы, нижеподписавшиеся, представитель ООО "РИ-ИНВЕСТ" , и представитель ООО «МКАИР»,
B13: =CONCATENATE("составили настоящий акт о том, что ",TEXT(C3,"ДД.ММ.ГГГГ"), " сданы в поверку следующие средства измерений:") -> составили настоящий акт о том, что 07.04.2025 сданы в поверку следующие средства измерений: | M13: =CONCATENATE("составили настоящий акт о том, что ",TEXT(C4,"ДД.ММ.ГГГГ"), " выданы с поверки следующие средства измерений:") -> составили настоящий акт о том, что 11.04.2025 выданы с поверки следующие средства измерений:
B15: 1 | C15: Газоанализатор СГОЭС номер 69964 | M15: 1 | N15: =C15 -> Газоанализатор СГОЭС номер 69964
B16: 2 | C16: Газоанализатор СГОЭС номер 69830 | M16: 2 | N16: =C16 -> Газоанализатор СГОЭС номер 69830
B17: 3 | C17: Газоанализатор СГОЭС номер 68826 | M17: 3 | N17: =C17 -> Газоанализатор СГОЭС номер 68826
B18: 4 | C18: Газоанализатор СГОЭС номер 68755 | M18: 4 | N18: =C18 -> Газоанализатор СГОЭС номер 68755
B19: 5 | C19: Газоанализатор СГОЭС номер 68769 | M19: 5 | N19: =C19 -> Газоанализатор СГОЭС номер 68769
B20: 6 | C20: Газоанализатор СГОЭС номер 66616 | M20: 6 | N20: =C20 -> Газоанализатор СГОЭС номер 66616
B21: 7 | C21: Газоанализатор СГОЭС номер 69949 | M21: 7 | N21: =C21 -> Газоанализатор СГОЭС номер 69949
B22: 8 | C22: Газоанализатор СГОЭС номер 71036 | M22: 8 | N22: =C22 -> Газоанализатор СГОЭС номер 71036
B23: 9 | C23: Газоанализатор СГОЭС номер 68812 | M23: 9 | N23: =C23 -> Газоанализатор СГОЭС номер 68812
B24: 10 | C24: Газоанализатор СГОЭС номер 68726 | M24: 10 | N24: =C24 -> Газоанализатор СГОЭС номер 68726
B25: 11 | C25: Газоанализатор СГОЭС номер 68817 | M25: 11 | N25: =C25 -> Газоанализатор СГОЭС номер 68817
B26: 12 | C26: Газоанализатор СГОЭС номер 67643 | M26: 12 | N26: =C26 -> Газоанализатор СГОЭС номер 67643
... B136: 122 | C136: Уровнемер Liquicap M FMI51 номер K802EC010F0 | M136: 122 | N136: =C136 -> Уровнемер Liquicap M FMI51 номер K802EC010F0
B137: 123 | M137: 123 | N137: =C137 -> 0
B138: 124 | M138: 124 | N138: =C138 -> 0
B139: 125 | M139: 125 | N139: =C139 -> 0
B140: 126 | M140: 126 | N140: =C140 -> 0
B141: 127 | M141: 127 | N141: =C141 -> 0
B142: 128 | M142: 128 | N142: =C142 -> 0
B143: 129 | M143: 129 | N143: =C143 -> 0
B144: 130 | M144: 130 | N144: =C144 -> 0
B145: 131 | M145: 131 | N145: =C145 -> 0
B146: 132 | M146: 132 | N146: =C146 -> 0
B147: 133 | M147: 133 | N147: =C147 -> 0
B148: 134 | M148: 134 | N148: =C148 -> 0
... B184: 170 | M184: 170 | N184: =C184 -> 0
B185: 171 | M185: 171
B186: 172 | M186: 172
B187: 173 | M187: 173
...

Sheet 4
B1: Номер акта | D1: 4
B2: дата
B3: приемки | C3: =VLOOKUP(D1,'Акты п-п'!$C$5:$I$57,2) -> 45755
B4: выдачи | C4: =VLOOKUP(D1,'Акты п-п'!$C$5:$I$57,3) -> 45757
C5: =VLOOKUP(D1,'Акты п-п'!$C$5:$I$57,5) -> Манджеев А.А.
C6: =VLOOKUP(D1,'Акты п-п'!$C$5:$I$57,7) -> Попов Е.В.
C7: =VLOOKUP(D1,'Акты п-п'!$C$5:$I$57,4) -> ООО «ГАЗПРОМНЕФТЬ-ЯМАЛ»
B9: АКТ | M9: АКТ
B10: приема-передачи СИ | M10: приема-передачи СИ
B12: =CONCATENATE("Мы, нижеподписавшиеся, представитель ",C7," , и представитель ООО «МКАИР», ") -> Мы, нижеподписавшиеся, представитель ООО «ГАЗПРОМНЕФТЬ-ЯМАЛ» , и представитель ООО «МКАИР», | M12: =B12 -> Мы, нижеподписавшиеся, представитель ООО «ГАЗПРОМНЕФТЬ-ЯМАЛ» , и представитель ООО «МКАИР»,
B13: =CONCATENATE("составили настоящий акт о том, что ",TEXT(C3,"ДД.ММ.ГГГГ"), " сданы в поверку следующие средства измерений:") -> составили настоящий акт о том, что 08.04.2025 сданы в поверку следующие средства измерений: | M13: =CONCATENATE("составили настоящий акт о том, что ",TEXT(C4,"ДД.ММ.ГГГГ"), " выданы с поверки следующие средства измерений:") -> составили настоящий акт о том, что 10.04.2025 выданы с поверки следующие средства измерений:
B15: 1 | C15: Термометр биметаллический S5500 номер 1107316965 | M15: 1 | N15: =C15 -> Термометр биметаллический S5500 номер 1107316965
B16: 2 | C16: Термометр биметаллический S55 номер 1106I4Y8 | M16: 2 | N16: =C16 -> Термометр биметаллический S55 номер 1106I4Y8
B17: 3 | C17: Термометр биметаллический S55 номер 1107АD6B | M17: 3 | N17: =C17 -> Термометр биметаллический S55 номер 1107АD6B
B18: 4 | C18: Термометр биметаллический S5500 номер 1107335159 | M18: 4 | N18: =C18 -> Термометр биметаллический S5500 номер 1107335159
B19: 5 | C19: Термометр биметаллический S55 номер 1107335158 | M19: 5 | N19: =C19 -> Термометр биметаллический S55 номер 1107335158
B20: 6 | C20: Манометр ТМ серия 20 номер 3017026 | M20: 6 | N20: =C20 -> Манометр ТМ серия 20 номер 3017026
B21: 7 | C21: Манометр ТМ серия 20 номер 3017021 | M21: 7 | N21: =C21 -> Манометр ТМ серия 20 номер 3017021
B22: 8 | C22: Манометр ТМ серия 20 номер 3017196 | M22: 8 | N22: =C22 -> Манометр ТМ серия 20 номер 3017196
B23: 9 | C23: Манометр ТМ серия 20 номер 3017188 | M23: 9 | N23: =C23 -> Манометр ТМ серия 20 номер 3017188
B24: 10 | C24: Манометр ТМ серия 20 номер 3017181 | M24: 10 | N24: =C24 -> Манометр ТМ серия 20 номер 3017181
B25: 11 | C25: Манометр ТМ серия 20 номер 3017190 | M25: 11 | N25: =C25 -> Манометр ТМ серия 20 номер 3017190
B26: 12 | C26: Манометр ТМ серия 20 номер 3016942 | M26: 12 | N26: =C26 -> Манометр ТМ серия 20 номер 3016942
... B95: 81 | C95: Манометр 233.50 номер 00702UP6 | M95: 81 | N95: =C95 -> Манометр 233.50 номер 00702UP6
B96: 82 | M96: 82 | N96: =C96 -> 0
B97: 83 | M97: 83 | N97: =C97 -> 0
B98: 84 | M98: 84 | N98: =C98 -> 0
B99: 85 | M99: 85 | N99: =C99 -> 0
B100: 86 | M100: 86 | N100: =C100 -> 0
B101: 87 | M101: 87 | N101: =C101 -> 0
B102: 88 | M102: 88 | N102: =C102 -> 0
B103: 89 | M103: 89 | N103: =C103 -> 0
B104: 90 | M104: 90 | N104: =C104 -> 0
B105: 91 | M105: 91 | N105: =C105 -> 0
B106: 92 | M106: 92 | N106: =C106 -> 0
B107: 93 | M107: 93 | N107: =C107 -> 0
... B1132: 1118 | M1132: 1118 | N1132: =C1132 -> 0
B1134: =CONCATENATE("Принял представитель ООО ""МКАИР"" ",C5) -> Принял представитель ООО "МКАИР" Манджеев А.А. | J1134: =C3 -> 45755 | M1134: =CONCATENATE("Сдал представитель ООО ""МКАИР"" ",C5) -> Сдал представитель ООО "МКАИР" Манджеев А.А. | Q1134: =C4 -> 45757
B1135: Должность, Ф. И.О., подпись | M1135: Должность, Ф. И.О., подпись
B1137: =CONCATENATE("Сдал представитель ",C7," ",C6) -> Сдал представитель ООО «ГАЗПРОМНЕФТЬ-ЯМАЛ» Попов Е.В. | J1137: =J1134 -> 45755 | M1137: =CONCATENATE("Принял представитель ", C7," ",,C6) -> Принял представитель ООО «ГАЗПРОМНЕФТЬ-ЯМАЛ» Попов Е.В. | Q1137: =Q1134 -> 45757
...

Sheet 5
B1: Номер акта | D1: 5
B2: дата
B3: приемки | C3: =VLOOKUP(D1,'Акты п-п'!$C$5:$I$57,2) -> 45761
B4: выдачи | C4: =VLOOKUP(D1,'Акты п-п'!$C$5:$I$57,3) -> 45765
C5: =VLOOKUP(D1,'Акты п-п'!$C$5:$I$57,5) -> Кадыков П.Ю.
C6: Астахов Е.А.
C7: =VLOOKUP(D1,'Акты п-п'!$C$5:$I$57,4) -> ООО "РИ-ИНВЕСТ"
B9: АКТ | M9: АКТ
B10: приема-передачи СИ | M10: приема-передачи СИ
B12: =CONCATENATE("Мы, нижеподписавшиеся, представитель ",C7," , и представитель ООО «МКАИР», ") -> Мы, нижеподписавшиеся, представитель ООО "РИ-ИНВЕСТ" , и представитель ООО «МКАИР», | M12: =B12 -> Мы, нижеподписавшиеся, представитель ООО "РИ-ИНВЕСТ" , и представитель ООО «МКАИР»,
B13: =CONCATENATE("составили настоящий акт о том, что ",TEXT(C3,"ДД.ММ.ГГГГ"), " сданы в поверку следующие средства измерений:") -> составили настоящий акт о том, что 14.04.2025 сданы в поверку следующие средства измерений: | M13: =CONCATENATE("составили настоящий акт о том, что ",TEXT(C4,"ДД.ММ.ГГГГ"), " выданы с поверки следующие средства измерений:") -> составили настоящий акт о том, что 18.04.2025 выданы с поверки следующие средства измерений:
B15: 1 | C15: Манометр МТИф номер 919422 | M15: 1 | N15: =C15 -> Манометр МТИф номер 919422
B16: 2 | C16: Манометр МП3-Уф номер 1014826 | M16: 2 | N16: =C16 -> Манометр МП3-Уф номер 1014826
B17: 3 | C17: Манометр МП4-Уф номер 007766 | M17: 3 | N17: =C17 -> Манометр МП4-Уф номер 007766
B18: 4 | C18: Манометр МП4-УУ2 номер Р00079 | M18: 4 | N18: =C18 -> Манометр МП4-УУ2 номер Р00079
B19: 5 | C19: Манометр МП4-УУ2 номер Р00163 | M19: 5 | N19: =C19 -> Манометр МП4-УУ2 номер Р00163
B20: 6 | C20: Манометр МП4-Уф номер 01310 | M20: 6 | N20: =C20 -> Манометр МП4-Уф номер 01310
B21: 7 | C21: Манометр 232.50.160 номер 02386 | M21: 7 | N21: =C21 -> Манометр 232.50.160 номер 02386
B22: 8 | C22: Манометр МП4-УУ2 номер 02423 | M22: 8 | N22: =C22 -> Манометр МП4-УУ2 номер 02423
B23: 9 | C23: Манометр МП4-Уф номер 02424 | M23: 9 | N23: =C23 -> Манометр МП4-Уф номер 02424
B24: 10 | C24: Манометр МП4-Уф номер 02425 | M24: 10 | N24: =C24 -> Манометр МП4-Уф номер 02425
B25: 11 | C25: Манометр 232.50.160 номер 03622 | M25: 11 | N25: =C25 -> Манометр 232.50.160 номер 03622
B26: 12 | C26: Манометр МП4-Уф номер 03631 | M26: 12 | N26: =C26 -> Манометр МП4-Уф номер 03631
... B460: 446 | C460: Уровнемер VEGAFLEX61 номер 16627268 | M460: 446 | N460: =C460 -> Уровнемер VEGAFLEX61 номер 16627268
B461: 447 | M461: 447 | N461: =C461 -> 0
B462: 448 | M462: 448 | N462: =C462 -> 0
B463: 449 | M463: 449 | N463: =C463 -> 0
B464: 450 | M464: 450 | N464: =C464 -> 0
B465: 451 | M465: 451 | N465: =C465 -> 0
B466: 452 | M466: 452 | N466: =C466 -> 0
B467: 453 | M467: 453 | N467: =C467 -> 0
B468: 454 | M468: 454 | N468: =C468 -> 0
B469: 455 | M469: 455 | N469: =C469 -> 0
B470: 456 | M470: 456 | N470: =C470 -> 0
B471: 457 | M471: 457 | N471: =C471 -> 0
B472: 458 | M472: 458 | N472: =C472 -> 0
... B515: 501 | M515: 501 | N515: =C515 -> 0
B517: =CONCATENATE("Принял представитель ООО ""МКАИР"" ",C5) -> Принял представитель ООО "МКАИР" Кадыков П.Ю. | J517: =C3 -> 45761 | M517: =CONCATENATE("Сдал представитель ООО ""МКАИР"" ",C5) -> Сдал представитель ООО "МКАИР" Кадыков П.Ю. | Q517: =C4 -> 45765
B518: Должность, Ф. И.О., подпись | M518: Должность, Ф. И.О., подпись
B520: =CONCATENATE("Сдал представитель ",C7," ",C6) -> Сдал представитель ООО "РИ-ИНВЕСТ" Астахов Е.А. | J520: =J517 -> 45761 | M520: =CONCATENATE("Принял представитель ", C7," ",,C6) -> Принял представитель ООО "РИ-ИНВЕСТ" Астахов Е.А. | Q520: =Q517 -> 45765
...

Sheet 6
B1: Номер акта | D1: 6
B2: дата
B3: приемки | C3: =VLOOKUP(D1,'Акты п-п'!$C$5:$I$57,2) -> 45759
B4: выдачи | C4: =VLOOKUP(D1,'Акты п-п'!$C$5:$I$57,3) -> 45761
C5: =VLOOKUP(D1,'Акты п-п'!$C$5:$I$57,5) -> Манджеев А.А.
C6: =VLOOKUP(D1,'Акты п-п'!$C$5:$I$57,7) -> Попов Е.В.
C7: =VLOOKUP(D1,'Акты п-п'!$C$5:$I$57,4) -> ООО «ГАЗПРОМНЕФТЬ-ЯМАЛ»
B9: АКТ | M9: АКТ
B10: приема-передачи СИ | M10: приема-передачи СИ
B12: =CONCATENATE("Мы, нижеподписавшиеся, представитель ",C7," , и представитель ООО «МКАИР», ") -> Мы, нижеподписавшиеся, представитель ООО «ГАЗПРОМНЕФТЬ-ЯМАЛ» , и представитель ООО «МКАИР», | M12: =B12 -> Мы, нижеподписавшиеся, представитель ООО «ГАЗПРОМНЕФТЬ-ЯМАЛ» , и представитель ООО «МКАИР»,
B13: =CONCATENATE("составили настоящий акт о том, что ",TEXT(C3,"ДД.ММ.ГГГГ"), " сданы в поверку следующие средства измерений:") -> составили настоящий акт о том, что 12.04.2025 сданы в поверку следующие средства измерений: | M13: =CONCATENATE("составили настоящий акт о том, что ",TEXT(C4,"ДД.ММ.ГГГГ"), " выданы с поверки следующие средства измерений:") -> составили настоящий акт о том, что 14.04.2025 выданы с поверки следующие средства измерений:
B15: 1 | C15: Газоанализатор ДГС ЭРИС номер ER230170898 | M15: 1 | N15: =C15 -> Газоанализатор ДГС ЭРИС номер ER230170898
B16: 2 | C16: Преобразователь давления 3051S номер 09962558 | M16: 2 | N16: =C16 -> Преобразователь давления 3051S номер 09962558
B17: 3 | C17: Преобразователь давления 3051S номер 09779082 | M17: 3 | N17: =C17 -> Преобразователь давления 3051S номер 09779082
